<?xml version="1.0"?>
<robot name="sphere_robot">

  <!-- Fixed base link -->
  <link name="base_link"/>

  <!-- Intermediate links for TODO set low inertia translations -->
  <link name="x_link">
    <inertial>
      <mass value="0.01"/>
      <origin xyz="0 0 0" rpy="0 0 0"/>
      <inertia ixx="0.0001" ixy="0" ixz="0" iyy="0.0001" iyz="0" izz="0.0001"/>
    </inertial>
  </link>
  
  <link name="y_link">
    <inertial>
      <mass value="0.01"/>
      <origin xyz="0 0 0" rpy="0 0 0"/>
      <inertia ixx="0.0001" ixy="0" ixz="0" iyy="0.0001" iyz="0" izz="0.0001"/>
    </inertial>
  </link>
  
  <link name="z_link">
    <inertial>
      <mass value="0.01"/>
      <origin xyz="0 0 0" rpy="0 0 0"/>
      <inertia ixx="0.0001" ixy="0" ixz="0" iyy="0.0001" iyz="0" izz="0.0001"/>
    </inertial>
  </link>

  <!-- Yaw link -->
  <link name="yaw_link"/>

  <!-- Sphere link representing the robot -->
  <link name="sphere_link">
    <inertial>
      <mass value="1.0"/>
      <origin xyz="0 0 0" rpy="0 0 0"/>
      <inertia ixx="0.225" ixy="0" ixz="0" iyy="0.225" iyz="0" izz="0.225"/>
    </inertial>
    <visual>
      <geometry>
        <!-- <sphere radius="0.5"/> -->
        <box size="1.2 0.6 0.5"/>
      </geometry>
    </visual>
    <collision>
      <geometry>
        <!-- <sphere radius="0.5"/> -->
        <box size="1.2 0.6 0.5"/>
      </geometry>
    </collision>
  </link>

  <!-- Prismatic joints for translation in world frame -->
  <joint name="joint_x" type="prismatic">
    <parent link="base_link"/>
    <child link="x_link"/>
    <origin xyz="0 0 0" rpy="0 0 0"/>
    <axis xyz="1 0 0"/> <!-- Moves along world's x-axis -->
    <limit lower="-10" upper="10" effort="1000" velocity="5"/>
  </joint>

  <joint name="joint_y" type="prismatic">
    <parent link="x_link"/>
    <child link="y_link"/>
    <origin xyz="0 0 0" rpy="0 0 0"/>
    <axis xyz="0 1 0"/> <!-- Moves along world's y-axis -->
    <limit lower="-10" upper="10" effort="1000" velocity="5"/>
  </joint>

  <joint name="joint_z" type="prismatic">
    <parent link="y_link"/>
    <child link="z_link"/>
    <origin xyz="0 0 0" rpy="0 0 0"/>
    <axis xyz="0 0 1"/> <!-- Moves along world's z-axis -->
    <limit lower="0" upper="10" effort="1000" velocity="5"/>
  </joint>

  <!-- Yaw joint (revolute) rotating about sphere's center -->
  <joint name="joint_yaw" type="revolute">
    <parent link="z_link"/>
    <child link="yaw_link"/>
    <origin xyz="0 0 0" rpy="0 0 0"/>
    <axis xyz="0 0 1"/>
    <limit lower="-3.1416" upper="3.1416" effort="1000" velocity="3.1416"/>
  </joint>

  <!-- Fixed joint attaching the sphere to yaw_link -->
  <joint name="joint_fixed" type="fixed">
    <parent link="yaw_link"/>
    <child link="sphere_link"/>
    <origin xyz="0 0 0" rpy="0 0 0"/>
  </joint>

</robot>
